<?xml version="1.0"?>

<robot name="cititruck_manipulator" xmlns:xacro="http://ros.org/wiki/xacro">


  <!-- Import all Gazebo-customization elements, including Gazebo colors -->
  <xacro:include filename="$(find cititruck_description)/urdf/cititruck_manipulator.gazebo" />
  <!-- Import Rviz colors -->
  <xacro:include filename="$(find cititruck_description)/urdf/materials.xacro" />

  <xacro:property name="forks_pidP" value="2000" />
  <xacro:property name="forks_pidI" value="0" />
  <xacro:property name="forks_pidD" value="10" />
  
  <xacro:property name="forks_low" value="0.08" />    
  <xacro:property name="forks_high" value="0.2" />
  
  <xacro:property name="forks_maxeffort" value="1000" />

  <!-- base_footprint is a fictitious link(frame) that is on the ground right below base_link origin, navigation stack dedpends on this frame and KDL needs a root link without any intertia -->
    <link name="base_footprint">
    </link>

    <joint name="base_footprint_joint" type="fixed">
      <origin xyz="0 0 0.050" rpy="0 0 0" />
      <child link="base_link" />
      <parent link="base_footprint"/>
    </joint>

  <!-- Base Link -->
  <link name="base_link">
    <inertial>
      <mass value="20"/>
      <inertia ixx="1" ixy="0" ixz="0" iyy="1" iyz="0" izz="1" />
      <origin/>
    </inertial>
    <visual>
      <origin xyz="0.8 0 0.4" rpy="0 0 0" />
      <geometry>
        <box size="0.4 0.55 0.75" />
      </geometry>
      <material name="blue"/>
    </visual>
    
    <collision>
      <origin xyz="0.8 0 0.1" rpy="0 0 0" />
      <geometry>
        <box size="0.4 0.55 0.005" />
      </geometry>
    </collision>
  </link>
  
    <link name="left_fork">
      <inertial>
        <mass value="1" />
        <origin xyz="0 0 0.0" />
        <inertia ixx="0.01" ixy="0.0" ixz="0.0"
                 iyy="0.01" iyz="0.0" izz="0.01" />
      </inertial>
      <visual>
        <origin xyz="0 0 0.0" rpy="0 0 0" />
        <geometry>
          <box size="0.8 0.1 0.01" />
        </geometry>
        
        <material name="grey" />
      </visual>
      <collision>
        <origin xyz="0 0 0.0" rpy="0 0 0" />
        <geometry>
          <box size="0.8 0.1 0.01" />
        </geometry>
	<contact_coefficients mu="1" kp="10.0" kd="10.0"/> -->
      </collision>
    </link>

    <link name="right_fork">
      <inertial>
        <mass value="1" />
        <origin xyz="0 0 0.0" />
        <inertia ixx="0.01" ixy="0.0" ixz="0.0"
                 iyy="0.01" iyz="0.0" izz="0.01" />
      </inertial>
      <visual>
        <origin xyz="0 0 0.0" rpy="0 0 0" />
        <geometry>
          <box size="0.8 0.1 0.01" />
        </geometry>
        
        <material name="grey" />
      </visual>
      <collision>
        <origin xyz="0 0 0.0" rpy="0 0 0" />
        <geometry>
          <box size="0.8 0.1 0.01" />
        </geometry>
	<contact_coefficients mu="1" kp="10.0" kd="10.0"/> -->
      </collision>
    </link>

    <link name="base_fork">
      <inertial>
        <mass value="0.1" />
        <origin xyz="0 0 0.0" />
        <inertia ixx="0.01" ixy="0.0" ixz="0.0"
                 iyy="0.01" iyz="0.0" izz="0.01" />
      </inertial>
      <visual>
        <origin xyz="0 0 0.0" rpy="0 0 0" />
        <geometry>
          <box size="0.01 0.01 0.01" />
        </geometry>
        
        <material name="grey" />
      </visual>
    </link>

    <!-- static joint connect the single prismatic joint with the forks... -->
    <joint name="left_fork_joint" type="fixed">
      <origin xyz="0 0.205 0.0" rpy="0 0 0" />
      <child link="left_fork" />
      <parent link="base_fork"/>
    </joint>

    <joint name="right_fork_joint" type="fixed">
      <origin xyz="0 -0.205 0.0" rpy="0 0 0" />
      <child link="right_fork" />
      <parent link="base_fork"/>
    </joint>


    <joint name="fork_joint" type="prismatic">
      <origin xyz="0.18 0.0 0.0" rpy="0 0 0" />
      <parent link="base_link" />
      <child link="base_fork"/>
      <axis xyz="0 0 1" />
      <limit lower="-1" upper="1" effort="1000" velocity="100" />
    </joint>

<!--
    <transmission name="fork_trans">
      <type>transmission_interface/SimpleTransmission</type>
      <joint name="fork_joint">
	<hardwareInterface>EffortJointInterface</hardwareInterface>
      </joint>
      <actuator name="fork_motor">
	<hardwareInterface>EffortJointInterface</hardwareInterface>
	<mechanicalReduction>1</mechanicalReduction>
      </actuator>
    </transmission>
-->
      <link name="steer_link">
        <inertial>
          <mass value="0.01"/>
          <inertia ixx="0.001" ixy="0" ixz="0" iyy="0.001" iyz="0" izz="0.001" />
          <origin/>
        </inertial>
        <visual>
          <origin xyz="0 0 0" rpy="0 0 0" />
          <geometry>
            <box size="0.1 0.1 0.1" />
          </geometry>
          <material name="orange"/>
        </visual>
      </link>
      
      <link name="sd_wheel_link">
        <inertial>
          <mass value="10"/>
          <inertia ixx="0.01" ixy="0" ixz="0" iyy="0.01" iyz="0" izz="0.01" />
          <origin/>
        </inertial>
        <visual>
          <origin xyz="0 0 0" rpy="1.57 0 0" />
          <geometry>
            <cylinder radius="0.08" length=".04" />
          </geometry>
          <material name="black"/>
        </visual>
        
        <collision>
          <origin xyz="0 0 0" rpy="1.57 0 0" />
          <geometry>
            <cylinder radius="0.08" length=".04" />
          </geometry>
        </collision>
      </link>

      <joint name="base2steer_joint" type="revolute">
        <parent link="base_link"/>
        <child link="steer_link"/>
        <limit effort="10000.0" lower="-1.57" upper="1.57" velocity="100"/>
        <origin xyz="1.190 0 0.04" rpy="0 0 0" />
        <axis xyz="0 0 1" />
      </joint>
<!--
    <transmission name="base2steer_trans">
      <type>transmission_interface/SimpleTransmission</type>
      <joint name="base2steer_joint">
	<hardwareInterface>EffortJointInterface</hardwareInterface>
      </joint>
      <actuator name="base2steer_motor">
	<hardwareInterface>EffortJointInterface</hardwareInterface>
	<mechanicalReduction>1</mechanicalReduction>
      </actuator>
    </transmission>
-->
      <joint name="steer2sd_wheel_joint" type="continuous">
        <parent link="steer_link"/>
        <child link="sd_wheel_link"/>
        <limit effort="10000.0" velocity="100"/>
        <origin xyz="0 0 0" rpy="0 0 0" />
        <axis xyz="0 1 0" />
      </joint>

<!--
    <transmission name="steer2sd_wheel_trans">
      <type>transmission_interface/SimpleTransmission</type>
      <joint name="steer2sd_wheel_joint">
	<hardwareInterface>EffortJointInterface</hardwareInterface>
      </joint>
      <actuator name="steer2sd_wheel_motor">
	<hardwareInterface>EffortJointInterface</hardwareInterface>
	<mechanicalReduction>1</mechanicalReduction>
      </actuator>
    </transmission>
-->
      <link name="fixed_left_wheel_link">
        <inertial>
          <mass value="0.1"/>
          <inertia ixx="0.01" ixy="0" ixz="0" iyy="0.01" iyz="0" izz="0.01" />
          <origin/>
        </inertial>
        <visual>
          <origin xyz="0 0 0" rpy="1.57 0 0" />
          <geometry>
            <cylinder radius="0.04" length=".08" />
          </geometry>
          <material name="gray"/>
        </visual>
        
        <collision>
          <origin xyz="0 0 0" rpy="1.57 0 0" />
          <geometry>
            <cylinder radius="0.04" length=".08" />
          </geometry>
         <!-- <contact_coefficients mu="100" kp="10.0" kd="0.1"/> -->
        </collision>
      </link>
      
      <joint name="base2fixed_left_wheel_joint" type="continuous">
        <parent link="base_link"/>
        <child link="fixed_left_wheel_link"/>
        <origin xyz="0 0.205 0" rpy="0 0 0" />
        <axis xyz="0 1 0" />
      </joint>
      
      <link name="fixed_right_wheel_link">
        <inertial>
          <mass value="0.1"/>
          <inertia ixx="0.01" ixy="0" ixz="0" iyy="0.01" iyz="0" izz="0.01" />
          <origin/>
        </inertial>
        <visual>
          <origin xyz="0 0 0" rpy="1.57 0 0" />
          <geometry>
            <cylinder radius="0.04" length=".08" />
          </geometry>
          <material name="gray"/>
        </visual>
        
        <collision>
          <origin xyz="0 0 0" rpy="1.57 0 0" />
          <geometry>
            <cylinder radius="0.04" length=".08" />
          </geometry>
         <!-- <contact_coefficients mu="100" kp="10.0" kd="0.1"/> -->
        </collision>
      </link>

      <joint name="base2fixed_right_wheel_joint" type="continuous">
        <parent link="base_link"/>
        <child link="fixed_right_wheel_link"/>
        <origin xyz="0 -0.205 0" rpy="0 0 0" />
        <axis xyz="0 1 0" />
      </joint>

      <!-- Sick laser -->
      <link name="laser_link">
	<collision>
	  <origin xyz="0 0 0" rpy="0 0 0"/>
	  <geometry>
	    <box size="0.1 0.1 0.1"/>
	  </geometry>
	</collision>
	
	<visual>
	  <origin xyz="0 0 0" rpy="0 0 0"/>
	  <geometry>
            <mesh filename="package://cititruck_description/meshes/sick_s300_laser.dae"/>
	  </geometry>
	</visual>
	
	<inertial>
	  <mass value="1e-5" />
	  <origin xyz="0 0 0" rpy="0 0 0"/>
	  <inertia ixx="1e-6" ixy="0" ixz="0" iyy="1e-6" iyz="0" izz="1e-6" />
	</inertial>
      </link>

      <joint name="laser_joint" type="fixed">
	<axis xyz="0 1 0" />
	<origin xyz="1.4 0 0.02" rpy="3.14159 0 0"/>
	<parent link="base_link"/>
	<child link="laser_link"/>
      </joint>


      <!-- Kinect -->      
      <link name="kinect_link">
	<collision>
	  <origin xyz="0 0 0" rpy="0 0 0"/>
	  <geometry>
	    <box size="0.1 0.1 0.1"/>
	  </geometry>
	</collision>
	
	<visual>
	  <origin xyz="0 0 0" rpy="0 0 0"/>
	  <geometry>
<!--             <mesh filename="package://cititruck_description/meshes/sick_s300_laser.dae"/> -->
	    <box size="0.001 0.001 0.001"/>
	  </geometry>
	</visual>
	
	<inertial>
	  <mass value="1e-5" />
	  <origin xyz="0 0 0" rpy="0 0 0"/>
	  <inertia ixx="1e-6" ixy="0" ixz="0" iyy="1e-6" iyz="0" izz="1e-6" />
	</inertial>
      </link>

      <joint name="kinect_joint" type="fixed">
	<axis xyz="0 1 0" />
 	<origin xyz="0.5 0 0.7" rpy="0 2.5 0"/> <!-- 0 2.5 0 -->
<!--  	<origin xyz="0.5 0 0.7" rpy="0 3.14159 0"/> -->
	<parent link="base_link"/>
	<child link="kinect_link"/>
      </joint>
      
  
      <!-- Adding VITO ROBOT stuff -->
      <!-- MODELS -->
  <xacro:include filename="$(find vito_description)/model/torso.urdf.xacro"/>
<!--   <xacro:include filename="$(find vito_description)/model/table.urdf.xacro"/> -->
<!--   <xacro:include filename="$(find vito_description)/model/materials.urdf"/> -->
  <xacro:include filename="$(find lwr_description)/model/kuka_lwr.urdf.xacro"/>
  <xacro:include filename="$(find soft_hand_description)/model/soft_hand.urdf.xacro"/>
  
  <link name="vito_anchor" />
  
    <joint name="w_fixed" type="fixed">
      <origin xyz="0.75 0.0 0.77" rpy="0 0 0"/>
      <parent link="base_link" />
      <child link="vito_anchor" />
    </joint>

  
  <!-- BODY -->
    <!--Table. This goes in World-->
<!--    <xacro:model_table name="workbench"
                    parent="base_footprint"
                    length="0.725"
                    width="1.25"
                    height="0.910"
                    plate_thickness="0.05">
  <origin xyz="-1.25 0.625 0.00" rpy="0 0 0"/>
  </xacro:model_table> -->


  <!-- TORSO -->
  <xacro:model_torso name="torso" parent="vito_anchor">
    <origin xyz="0 0 0.0" rpy="0 0 0"/>
  </xacro:model_torso>
  
  <!-- LEFT ARM -->
  <xacro:kuka_lwr name="left_arm" parent="vito_anchor">
    <!-- <origin xyz="-0.1650   -0.0000    0.3814" rpy="-2.1588   -0.4478    1.8518"/> -->
    <origin xyz="-0.1650   -0.0000    0.3814" rpy="-2.617993877991494  -0.000000000000000   1.570796326794897"/>
  </xacro:kuka_lwr>

  <!-- LEFT SOFTHAND -->
 <!--  <xacro:soft_hand parent="left_arm_7_link" name="left_hand" left="true" withAdaptiveTransmission="true" useMimicTag="$(arg use_mimic_tag)">
    <origin xyz="0 0 0" rpy="0 0 0"/>
  </xacro:soft_hand> -->

  <!-- RIGHT ARM -->
  <xacro:kuka_lwr name="right_arm" parent="vito_anchor">
    <!-- <origin xyz="-0.165 0.10858 0.490" rpy="-1.5707963267948966 -0.5235987010713441 0.5235990737060282"/> -->
    <origin xyz="-0.1650    0.0000    0.5986" rpy="-0.281034901502814  -0.447832396928932   0.588002603547567"/>
  </xacro:kuka_lwr>

  <!-- RIGHT SOFTHAND -->
<!--  <xacro:soft_hand parent="right_arm_7_link" name="right_hand" left="false" withAdaptiveTransmission="false" useMimicTag="$(arg use_mimic_tag)">
    <origin xyz="0 0 0.0" rpy="0 0 0"/>
  </xacro:soft_hand>-->
  <xacro:soft_hand parent="right_arm_7_link" name="right_hand" left="false" withAdaptiveTransmission="false" useMimicTag="true">
    <origin xyz="0 0 0.0" rpy="0 0 3.14159"/>
  </xacro:soft_hand>

  <link name="ft_surface">
      <inertial>
        <mass value="0.1"/>
          <origin xyz="0 0 0.0" rpy="0 0 0"/>
            <inertia ixx="${1 / 12  * (3 * 0.05 * 0.05 + 0.01 * 0.01)}"  ixy="0"  ixz="0" iyy="${1 / 12  * (3 * 0.05 * 0.05 + 0.01 * 0.01)}" iyz="0" izz="${1 / 12  * (3 * 0.05 * 0.05 + 0.01 * 0.01)}" />
      </inertial>
      <visual>
        <origin xyz="0 0 0.0" rpy="0 0 0"/>
        <geometry>
          <sphere radius="0.001" />
        </geometry>
      </visual>

<!--       <collision>
        <origin xyz="0 0 0.0" rpy="0 0 0"/>
        <geometry>
          <sphere radius="0.02" />
        </geometry>
        <surface>
          <contact>
            <collide_bitmask>"0x11111"</collide_bitmask>
          </contact>
        </surface>
      </collision> -->

  </link>
  
  <joint name="ft_joint_sensor" type="fixed">
    <origin xyz="0.015 0.030 0.192" rpy="1.5708 0.0 1.5708"/>
    <parent link="right_arm_7_link" />
    <child link="ft_surface" />
  </joint>



  <link name="gripper_link">
      <inertial>
        <mass value="0.1"/>
          <origin xyz="0 0 0.0" rpy="0 0 0"/>
            <inertia ixx="${1 / 12  * (3 * 0.05 * 0.05 + 0.01 * 0.01)}"  ixy="0"  ixz="0" iyy="${1 / 12  * (3 * 0.05 * 0.05 + 0.01 * 0.01)}" iyz="0" izz="${1 / 12  * (3 * 0.05 * 0.05 + 0.01 * 0.01)}" />
      </inertial>
      <visual>
        <origin xyz="0 0 0.0" rpy="0 0 0"/>
        <geometry>
        <mesh filename="package://vito_description/meshes/gripper.stl"/>
        </geometry>
      </visual>

<!--       <collision>
        <origin xyz="0 0 0.0" rpy="0 0 0"/>
        <geometry>
          <sphere radius="0.02" />
        </geometry>
        <surface>
          <contact>
            <collide_bitmask>"0x11111"</collide_bitmask>
          </contact>
        </surface>
      </collision> -->

  </link>
  
  <joint name="gripper_joint" type="fixed">
    <origin xyz="0 0 0" rpy="0 0 0"/>
    <parent link="left_arm_7_link" />
    <child link="gripper_link" />
  </joint>



<!--   <gazebo reference="ft_surface_fake">
    <gravity>true</gravity>
  </gazebo>

    <gazebo>
      <plugin name="force_sensor" filename="libgazebo_ros_ft_sensor.so">
        <updateRate>100.0</updateRate>
        <topicName>ft_sensor_topic</topicName>
        <jointName>ft_joint_sensor</jointName>
      </plugin>
    </gazebo>

    <gazebo reference="ft_joint_sensor">
      <provideFeedback>true</provideFeedback>
      <disableFixedJointLumping>true</disableFixedJointLumping>
    </gazebo>  -->
</robot>
